Workbook

Sheet README
A1: Khamis-Roche calculation — student help
A2: A short walkthrough for calculating biological maturity from current height, current weight, and parents' heights, plus simple instructions for the four plots you need.
A4: What this workbook contains
A5: 1. Step-by-step — one worked example so you can see each calculation done by hand.
A6: 2. KR Coefficients — the lookup table for the regression coefficients.
A7: 3. Try it — a template with the formulas already wired up; paste your squad in and the columns recalculate.
A8: 4. Plot examples — what the four plots should look like and how to make them in Excel.
A10: What is Khamis-Roche?
A11: Khamis-Roche is a non-invasive method that estimates a child's predicted adult height (PAH) from three things they already know: current standing height, current weight, and their parents' heights. Once you have PAH, you compare it to the child's current height. The ratio is %PAH = (current height / PAH) × 100.
A12: %PAH tells you how far through their growth the child is. A child at 88% of their adult height is biologically less mature than a child at 95% — even if they are the same age in years.
A14: Maturity bands you will use
A15: Maturity classification (Khamis & Roche, 1994):
... A35: Khamis-Roche assumes parents' reported heights are accurate (they almost never are — people round up). It also assumes the child is biologically the offspring of the listed parents. Document these assumptions in your report.

Sheet Step-by-step
A1: Step-by-step worked example
A2: We will calculate %PAH for one boy in the U16 hockey squad. Follow each step. The same logic applies to every player.
A4: The player
A5: Inputs
A6: Name: Magnus Hansen
A7: Sex: Male
A8: Chronological age: 15.8 years
A9: Current height: 182 cm
A10: Current weight: 72 kg
A11: Mom's height: 168 cm
A12: Dad's height: 185 cm
A14: Step 1 — Adjusted mid-parental height
... A20: Magnus is a 15.8-year-old boy, so we use the row for sex='M' and age 15.5–16.5 in the KR Coefficients sheet:
A21: Sex | B21: Age range | C21: b0 | D21: b1 (height) | E21: b2 (weight) | F21: b3 (MPH_adj)
A22: M | B22: 15.5 - 16.5 | C22: 20 | D22: 0.5 | E22: 0.1 | F22: 0.4
A24: Step 3 — Calculate predicted adult height (PAH)
A25: Plug in:
A26: PAH = 20.0 + 0.50 × 182 + 0.10 × 72 + 0.40 × 183.0
A27: = 20.0 + 91.0 + 7.2 + 73.2
A28: = 191.4 cm
A30: Step 4 — Calculate %PAH
A31: %PAH = (182 / 191.4) × 100 = 95.1%
A33: Step 5 — Interpret
A34: Reading the result
A35: Magnus is at 95.1% of his predicted adult height.
A36: That puts him in the 'on time' band (88–96%), but on the upper edge.
A37: He is biologically more mature than a teammate at, say, 91% PAH —
... A43: See the Try it sheet for a working version with cell references.

Sheet KR Coefficients
A1: Khamis-Roche regression coefficients
A2: Use the row that matches the player's sex and chronological age.
A4: Sex | B4: Age range (years) | C4: b0 | D4: b1 (height) | E4: b2 (weight) | F4: b3 (MPH_adj) | G4: Use for
A5: F | B5: 13.0 - 14.5 | C5: 30 | D5: 0.55 | E5: 0.1 | F5: 0.3 | G5: Most U14 girls
A6: F | B6: 14.5 - 15.5 | C6: 22 | D6: 0.65 | E6: 0.08 | F6: 0.25 | G6: Older U14 / younger U15 girls
A7: M | B7: 14.5 - 15.5 | C7: 25 | D7: 0.45 | E7: 0.12 | F7: 0.42 | G7: Younger U16 boys
A8: M | B8: 15.5 - 16.5 | C8: 20 | D8: 0.5 | E8: 0.1 | F8: 0.4 | G8: Older U16 boys
A10: Note: the published Khamis & Roche (1994) tables provide coefficients in 6-month age bands across the whole adolescent range. The four bands above cover the U14 girls and U16 boys squads in this assignment. If you need other ages, consult the original publication.

Sheet Try it
B1: Try it yourself
B2: Replace the sample rows below with your own players. The yellow columns recalculate automatically.
B4: # | C4: Name | D4: Sex | E4: Age (yr) | F4: Height (cm) | G4: Weight (kg) | H4: Mom h (cm) | I4: Dad h (cm) | J4: MPH_adj | K4: b0 | L4: b1 | M4: b2 | N4: b3 | O4: PAH (cm) | P4: %PAH | Q4: Maturity
B5: 1 | C5: Alma Sørensen | D5: F | E5: 13.6 | F5: 158 | G5: 47 | H5: 165 | I5: 178 | J5: =IF(D5="M",(H5+I5)/2+6.5,(H5+I5)/2-6.5) -> 165 | K5: =IF(D5="F",IF(E5<14.5,'KR Coefficients'!C5,'KR Coefficients'!C6),IF(E5<15.5,'KR Coefficients'!C7,'KR Coefficients'!C8)) -> 30 | L5: =IF(D5="F",IF(E5<14.5,'KR Coefficients'!D5,'KR Coefficients'!D6),IF(E5<15.5,'KR Coefficients'!D7,'KR Coefficients'!D8)) -> 0.55 | M5: =IF(D5="F",IF(E5<14.5,'KR Coefficients'!E5,'KR Coefficients'!E6),IF(E5<15.5,'KR Coefficients'!E7,'KR Coefficients'!E8)) -> 0.1 | N5: =IF(D5="F",IF(E5<14.5,'KR Coefficients'!F5,'KR Coefficients'!F6),IF(E5<15.5,'KR Coefficients'!F7,'KR Coefficients'!F8)) -> 0.3 | O5: =K5+L5*F5+M5*G5+N5*J5 -> 171.1 | P5: =F5/O5*100 -> 92.343659 | Q5: =IF(P5<88,"late",IF(P5>96,"early","on time")) -> on time
B6: 2 | C6: Freja Nielsen | D6: F | E6: 14.1 | F6: 168 | G6: 56 | H6: 172 | I6: 188 | J6: =IF(D6="M",(H6+I6)/2+6.5,(H6+I6)/2-6.5) -> 173.5 | K6: =IF(D6="F",IF(E6<14.5,'KR Coefficients'!C5,'KR Coefficients'!C6),IF(E6<15.5,'KR Coefficients'!C7,'KR Coefficients'!C8)) -> 30 | L6: =IF(D6="F",IF(E6<14.5,'KR Coefficients'!D5,'KR Coefficients'!D6),IF(E6<15.5,'KR Coefficients'!D7,'KR Coefficients'!D8)) -> 0.55 | M6: =IF(D6="F",IF(E6<14.5,'KR Coefficients'!E5,'KR Coefficients'!E6),IF(E6<15.5,'KR Coefficients'!E7,'KR Coefficients'!E8)) -> 0.1 | N6: =IF(D6="F",IF(E6<14.5,'KR Coefficients'!F5,'KR Coefficients'!F6),IF(E6<15.5,'KR Coefficients'!F7,'KR Coefficients'!F8)) -> 0.3 | O6: =K6+L6*F6+M6*G6+N6*J6 -> 180.05 | P6: =F6/O6*100 -> 93.307415 | Q6: =IF(P6<88,"late",IF(P6>96,"early","on time")) -> on time
B7: 3 | C7: Clara Pedersen | D7: F | E7: 13.4 | F7: 152 | G7: 42 | H7: 162 | I7: 175 | J7: =IF(D7="M",(H7+I7)/2+6.5,(H7+I7)/2-6.5) -> 162 | K7: =IF(D7="F",IF(E7<14.5,'KR Coefficients'!C5,'KR Coefficients'!C6),IF(E7<15.5,'KR Coefficients'!C7,'KR Coefficients'!C8)) -> 30 | L7: =IF(D7="F",IF(E7<14.5,'KR Coefficients'!D5,'KR Coefficients'!D6),IF(E7<15.5,'KR Coefficients'!D7,'KR Coefficients'!D8)) -> 0.55 | M7: =IF(D7="F",IF(E7<14.5,'KR Coefficients'!E5,'KR Coefficients'!E6),IF(E7<15.5,'KR Coefficients'!E7,'KR Coefficients'!E8)) -> 0.1 | N7: =IF(D7="F",IF(E7<14.5,'KR Coefficients'!F5,'KR Coefficients'!F6),IF(E7<15.5,'KR Coefficients'!F7,'KR Coefficients'!F8)) -> 0.3 | O7: =K7+L7*F7+M7*G7+N7*J7 -> 166.4 | P7: =F7/O7*100 -> 91.346154 | Q7: =IF(P7<88,"late",IF(P7>96,"early","on time")) -> on time
B8: 4 | C8: Magnus Hansen | D8: M | E8: 15.8 | F8: 182 | G8: 72 | H8: 168 | I8: 185 | J8: =IF(D8="M",(H8+I8)/2+6.5,(H8+I8)/2-6.5) -> 183 | K8: =IF(D8="F",IF(E8<14.5,'KR Coefficients'!C5,'KR Coefficients'!C6),IF(E8<15.5,'KR Coefficients'!C7,'KR Coefficients'!C8)) -> 20 | L8: =IF(D8="F",IF(E8<14.5,'KR Coefficients'!D5,'KR Coefficients'!D6),IF(E8<15.5,'KR Coefficients'!D7,'KR Coefficients'!D8)) -> 0.5 | M8: =IF(D8="F",IF(E8<14.5,'KR Coefficients'!E5,'KR Coefficients'!E6),IF(E8<15.5,'KR Coefficients'!E7,'KR Coefficients'!E8)) -> 0.1 | N8: =IF(D8="F",IF(E8<14.5,'KR Coefficients'!F5,'KR Coefficients'!F6),IF(E8<15.5,'KR Coefficients'!F7,'KR Coefficients'!F8)) -> 0.4 | O8: =K8+L8*F8+M8*G8+N8*J8 -> 191.4 | P8: =F8/O8*100 -> 95.088819 | Q8: =IF(P8<88,"late",IF(P8>96,"early","on time")) -> on time
B9: 5 | C9: Adam Knudsen | D9: M | E9: 15.6 | F9: 161 | G9: 55 | H9: 163 | I9: 174 | J9: =IF(D9="M",(H9+I9)/2+6.5,(H9+I9)/2-6.5) -> 175 | K9: =IF(D9="F",IF(E9<14.5,'KR Coefficients'!C5,'KR Coefficients'!C6),IF(E9<15.5,'KR Coefficients'!C7,'KR Coefficients'!C8)) -> 20 | L9: =IF(D9="F",IF(E9<14.5,'KR Coefficients'!D5,'KR Coefficients'!D6),IF(E9<15.5,'KR Coefficients'!D7,'KR Coefficients'!D8)) -> 0.5 | M9: =IF(D9="F",IF(E9<14.5,'KR Coefficients'!E5,'KR Coefficients'!E6),IF(E9<15.5,'KR Coefficients'!E7,'KR Coefficients'!E8)) -> 0.1 | N9: =IF(D9="F",IF(E9<14.5,'KR Coefficients'!F5,'KR Coefficients'!F6),IF(E9<15.5,'KR Coefficients'!F7,'KR Coefficients'!F8)) -> 0.4 | O9: =K9+L9*F9+M9*G9+N9*J9 -> 176 | P9: =F9/O9*100 -> 91.477273 | Q9: =IF(P9<88,"late",IF(P9>96,"early","on time")) -> on time
B10: 6 | C10: Valdemar Sørensen | D10: M | E10: 15.5 | F10: 188 | G10: 78 | H10: 170 | I10: 192 | J10: =IF(D10="M",(H10+I10)/2+6.5,(H10+I10)/2-6.5) -> 187.5 | K10: =IF(D10="F",IF(E10<14.5,'KR Coefficients'!C5,'KR Coefficients'!C6),IF(E10<15.5,'KR Coefficients'!C7,'KR Coefficients'!C8)) -> 20 | L10: =IF(D10="F",IF(E10<14.5,'KR Coefficients'!D5,'KR Coefficients'!D6),IF(E10<15.5,'KR Coefficients'!D7,'KR Coefficients'!D8)) -> 0.5 | M10: =IF(D10="F",IF(E10<14.5,'KR Coefficients'!E5,'KR Coefficients'!E6),IF(E10<15.5,'KR Coefficients'!E7,'KR Coefficients'!E8)) -> 0.1 | N10: =IF(D10="F",IF(E10<14.5,'KR Coefficients'!F5,'KR Coefficients'!F6),IF(E10<15.5,'KR Coefficients'!F7,'KR Coefficients'!F8)) -> 0.4 | O10: =K10+L10*F10+M10*G10+N10*J10 -> 196.8 | P10: =F10/O10*100 -> 95.528455 | Q10: =IF(P10<88,"late",IF(P10>96,"early","on time")) -> on time
B12: Yellow cells are calculated. Replace any blue input cell to see the values update.
B14: Legend: | C14: input | D14: calculated

Sheet Plot examples
A1: Simple plots in Excel
A2: Once your %PAH and birth-quarter columns are calculated, build these four plots. Use the small example tables below as a starting point — select the table, then Insert → Chart.
A4: Plot 1 — Distribution of %PAH (histogram)
A5: Goal: show how spread out the squad is in biological maturity. Select your %PAH column, then Insert → Insert Statistic Chart → Histogram. Excel will bin the values automatically.
A6: Tip: set the bin width to 1 or 2% so you can see clusters.
A8: Example data — %PAH for 20 players
A9: Player 1 | B9: 88.5
A10: Player 2 | B10: 89.7
A11: Player 3 | B11: 90.2
A12: Player 4 | B12: 90.8
A13: Player 5 | B13: 91.3
A14: Player 6 | B14: 91.9
A15: Player 7 | B15: 92
A16: Player 8 | B16: 92.4
A17: Player 9 | B17: 92.6
A18: Player 10 | B18: 93.1
A19: Player 11 | B19: 93.5
A20: Player 12 | B20: 93.8
... A28: Player 20 | B28: 97.1
A30: Plot 2 — Scatter: %PAH vs. birth month
A31: Goal: see whether biologically more mature players tend to be born earlier in the year (a sign that maturity and relative age move together). Select the two columns, then Insert → Scatter (X Y).
A33: Birth month | B33: %PAH
A34: 1 | B34: 88.5
A35: 1 | B35: 89.7
A36: 2 | B36: 90.2
A37: 2 | B37: 90.8
A38: 3 | B38: 91.3
A39: 3 | B39: 91.9
A40: 4 | B40: 92
A41: 4 | B41: 92.4
A42: 5 | B42: 92.6
A43: 5 | B43: 93.1
A44: 6 | B44: 93.5
A45: 7 | B45: 93.8
... A53: 12 | B53: 97.1
A55: Plot 3 — Bar: number of players per relative age quartile
A56: Goal: show whether birthdays are spread evenly across the year. Build a small count table (Q1–Q4 with the n in each), then Insert → Bar/Column chart.
A58: Quartile | B58: n players
A59: Q1 | B59: 9
A60: Q2 | B60: 6
...
